Workbook

Sheet Applications
A1: Date Applied | B1: Company | C1: Role Title | D1: Level | E1: Country | F1: City / Remote | G1: Fit Score (%) | H1: Channel | I1: Referral / Contact Name | J1: Sponsorship Question? | K1: Status | L1: Response Date | M1: Days to Response | N1: Next Action | O1: Next Action Date | P1: Notes | Q1: Interview/Screen Date(s) | R1: Gap Category | S1: Key Requirements | T1: Functional Fit (0-100) | U1: Seniority Fit (0-100) | V1: Domain Fit (0-100) | W1: Evidence Strength (0-100) | X1: Location/Auth Fit (0-100) | Y1: Competitive Positioning (0-100) | Z1: Relationship Access (0-100) | AA1: Strategic Fit Score | AB1: Pursuit Tier | AC1: Human Access Status | AD1: Outreach Count | AE1: Days Since Apply | AF1: Application Quality Flag
B2: eBay | C2: Lead Product Program Manager | D2: Lead | E2: Canada | F2: Toronto | G2: 55 | H2: Cold Portal | J2: No | K2: Rejected | L2: 46226 | M2: =IF(OR(L265="",A265=""),"",L265-A265) | P2: Rejected via Workday notification 07/23: "significant interest" in the role, decided not to move forward. Distinct from eBay Technical Program Manager, Search (Interviewing) and other eBay entries already logged. Original apply date not confirmed. ROLE (confirmed via posting, req R0073551, Toronto): "Lead Product Program Manager" — blends product management ownership with program delivery, more product-strategy-weighted than Elena's TPM/portfolio background. STRENGTHS: cross-functional delivery, executive communication. GAPS: product strategy/roadmap ownership (vs. program execution) is a lighter part of the resume; e-commerce/marketplace product domain not previously evidenced. | T2: =IF(G2="","",G2) | U2: =IF(C2="","",IF(OR(ISNUMBER(SEARCH("Director",C2)),ISNUMBER(SEARCH("Lead",C2)),ISNUMBER(SEARCH("Senior",C2)),ISNUMBER(SEARCH("Sr.",C2))),90,IF(OR(ISNUMBER(SEARCH("Manager",C2)),ISNUMBER(SEARCH("Program",C2)),ISNUMBER(SEARCH("Portfolio",C2))),80,60))) | V2: =IF(C2="","",IF(OR(ISNUMBER(SEARCH("AI",C2)),ISNUMBER(SEARCH("Data",C2)),ISNUMBER(SEARCH("Technology",C2)),ISNUMBER(SEARCH("Technical",C2)),ISNUMBER(SEARCH("Engineering",C2)),ISNUMBER(SEARCH("Platform",C2)),ISNUMBER(SEARCH("Portfolio",C2))),85,65)) | W2: =IF(C2="","",MIN(100,50+IF(S2<>"",25,0)+IF(R2<>"",15,0)+IF(P2<>"",10,0))) | X2: =IF(E2="","",IF(OR(E2="Canada",E2="CA"),100,IF(OR(E2="United States",E2="USA",E2="US"),IF(J2="Yes",45,75),65))) | Y2: =IF(C2="","",IF(OR(ISNUMBER(SEARCH("Program",C2)),ISNUMBER(SEARCH("Portfolio",C2)),ISNUMBER(SEARCH("Operations",C2)),ISNUMBER(SEARCH("Transformation",C2))),85,IF(ISNUMBER(SEARCH("Product Manager",C2)),55,70))) | Z2: =IF(C2="","",MIN(100,IF(I2<>"",60,10)+IF(AA2>0,MIN(40,AA2*20),0))) | AA2: =IF(T2="","",ROUND(T2*25%+U2*15%+V2*10%+W2*15%+X2*15%+Y2*10%+Z2*10%,0)) | AB2: =IF(AA2="","",IF(X2<50,"Selective / Barrier",IF(AA2>=80,"Tier 1 - Pursue",IF(AA2>=70,"Tier 2 - Pursue",IF(AA2>=60,"Tier 3 - Selective","Do Not Pursue"))))) | AC2: =IF(C2="","",IF(I2<>"","Named Contact",IF(AA2>0,"Outreach Logged","Cold"))) | AD2: =IF(B2="","",COUNTIF('Outreach Log'!$C:$C,B2)) | AE2: =IF(A2="","",IF(OR(K2="Rejected",K2="Closed"),IF(L2<>"",L2-A2,TODAY()-A2),TODAY()-A2)) | AF2: =IF(C2="","",IF(AND(AA2>=70,AC2="Cold"),"High-fit but cold",IF(AND(AA2<60,K2="Applied"),"Low-fit application",IF(AND(AA2>=70,OR(AC2="Named Contact",AC2="Outreach Logged")),"Targeted pursuit","Review"))))
B3: eBay | C3: Sr. Product Manager, Search AI | D3: Senior | E3: Canada | F3: Toronto | G3: 40 | H3: Cold Portal | J3: No | K3: Rejected | L3: 46245 | M3: =IF(OR(L266="",A266=""),"",L266-A266) | P3: Rejected via eBay Workday 08/11 3:40am ET - standard significant interest notice. Not previously logged; original apply date unknown. DISTINCT from Technical Program Manager, Search (R0074668) which remains at Interviewing. ROLE (confirmed via posting): this is a PRODUCT MANAGER role, not TPM — owns product strategy/roadmap for search AI/ML features, runs A/B tests, defines product vision with UX/design. GAPS: this is product ownership, not program delivery — a meaningfully different discipline from Elena's TPM/portfolio background; no direct product-management title or P&L/roadmap-ownership evidence in resume. Likely applied for AI-domain overlap, but role function mismatch explains the fast rejection. | T3: =IF(G3="","",G3) | U3: =IF(C3="","",IF(OR(ISNUMBER(SEARCH("Director",C3)),ISNUMBER(SEARCH("Lead",C3)),ISNUMBER(SEARCH("Senior",C3)),ISNUMBER(SEARCH("Sr.",C3))),90,IF(OR(ISNUMBER(SEARCH("Manager",C3)),ISNUMBER(SEARCH("Program",C3)),ISNUMBER(SEARCH("Portfolio",C3))),80,60))) | V3: =IF(C3="","",IF(OR(ISNUMBER(SEARCH("AI",C3)),ISNUMBER(SEARCH("Data",C3)),ISNUMBER(SEARCH("Technology",C3)),ISNUMBER(SEARCH("Technical",C3)),ISNUMBER(SEARCH("Engineering",C3)),ISNUMBER(SEARCH("Platform",C3)),ISNUMBER(SEARCH("Portfolio",C3))),85,65)) | W3: =IF(C3="","",MIN(100,50+IF(S3<>"",25,0)+IF(R3<>"",15,0)+IF(P3<>"",10,0))) | X3: =IF(E3="","",IF(OR(E3="Canada",E3="CA"),100,IF(OR(E3="United States",E3="USA",E3="US"),IF(J3="Yes",45,75),65))) | Y3: =IF(C3="","",IF(OR(ISNUMBER(SEARCH("Program",C3)),ISNUMBER(SEARCH("Portfolio",C3)),ISNUMBER(SEARCH("Operations",C3)),ISNUMBER(SEARCH("Transformation",C3))),85,IF(ISNUMBER(SEARCH("Product Manager",C3)),55,70))) | Z3: =IF(C3="","",MIN(100,IF(I3<>"",60,10)+IF(AA3>0,MIN(40,AA3*20),0))) | AA3: =IF(T3="","",ROUND(T3*25%+U3*15%+V3*10%+W3*15%+X3*15%+Y3*10%+Z3*10%,0)) | AB3: =IF(AA3="","",IF(X3<50,"Selective / Barrier",IF(AA3>=80,"Tier 1 - Pursue",IF(AA3>=70,"Tier 2 - Pursue",IF(AA3>=60,"Tier 3 - Selective","Do Not Pursue"))))) | AC3: =IF(C3="","",IF(I3<>"","Named Contact",IF(AA3>0,"Outreach Logged","Cold"))) | AD3: =IF(B3="","",COUNTIF('Outreach Log'!$C:$C,B3)) | AE3: =IF(A3="","",IF(OR(K3="Rejected",K3="Closed"),IF(L3<>"",L3-A3,TODAY()-A3),TODAY()-A3)) | AF3: =IF(C3="","",IF(AND(AA3>=70,AC3="Cold"),"High-fit but cold",IF(AND(AA3<60,K3="Applied"),"Low-fit application",IF(AND(AA3>=70,OR(AC3="Named Contact",AC3="Outreach Logged")),"Targeted pursuit","Review"))))
B4: eBay | C4: Program Manager: AI in Search | D4: Manager | E4: Canada | F4: Toronto | H4: Cold Portal | J4: No | K4: Rejected | L4: 46044 | M4: =IF(OR(L267="",A267=""),"",L267-A267) | P4: REJECTED 2026-01-22: eBay (ebay@myworkday.com) — "decided not to move forward." Date Applied unknown — Elena to confirm. Retroactively logged via full eBay inbox review 2026-09-12. | T4: =IF(G4="","",G4) | U4: =IF(C4="","",IF(OR(ISNUMBER(SEARCH("Director",C4)),ISNUMBER(SEARCH("Lead",C4)),ISNUMBER(SEARCH("Senior",C4)),ISNUMBER(SEARCH("Sr.",C4))),90,IF(OR(ISNUMBER(SEARCH("Manager",C4)),ISNUMBER(SEARCH("Program",C4)),ISNUMBER(SEARCH("Portfolio",C4))),80,60))) | V4: =IF(C4="","",IF(OR(ISNUMBER(SEARCH("AI",C4)),ISNUMBER(SEARCH("Data",C4)),ISNUMBER(SEARCH("Technology",C4)),ISNUMBER(SEARCH("Technical",C4)),ISNUMBER(SEARCH("Engineering",C4)),ISNUMBER(SEARCH("Platform",C4)),ISNUMBER(SEARCH("Portfolio",C4))),85,65)) | W4: =IF(C4="","",MIN(100,50+IF(S4<>"",25,0)+IF(R4<>"",15,0)+IF(P4<>"",10,0))) | X4: =IF(E4="","",IF(OR(E4="Canada",E4="CA"),100,IF(OR(E4="United States",E4="USA",E4="US"),IF(J4="Yes",45,75),65))) | Y4: =IF(C4="","",IF(OR(ISNUMBER(SEARCH("Program",C4)),ISNUMBER(SEARCH("Portfolio",C4)),ISNUMBER(SEARCH("Operations",C4)),ISNUMBER(SEARCH("Transformation",C4))),85,IF(ISNUMBER(SEARCH("Product Manager",C4)),55,70))) | Z4: =IF(C4="","",MIN(100,IF(I4<>"",60,10)+IF(AA4>0,MIN(40,AA4*20),0))) | AA4: =IF(T4="","",ROUND(T4*25%+U4*15%+V4*10%+W4*15%+X4*15%+Y4*10%+Z4*10%,0)) | AB4: =IF(AA4="","",IF(X4<50,"Selective / Barrier",IF(AA4>=80,"Tier 1 - Pursue",IF(AA4>=70,"Tier 2 - Pursue",IF(AA4>=60,"Tier 3 - Selective","Do Not Pursue"))))) | AC4: =IF(C4="","",IF(I4<>"","Named Contact",IF(AA4>0,"Outreach Logged","Cold"))) | AD4: =IF(B4="","",COUNTIF('Outreach Log'!$C:$C,B4)) | AE4: =IF(A4="","",IF(OR(K4="Rejected",K4="Closed"),IF(L4<>"",L4-A4,TODAY()-A4),TODAY()-A4)) | AF4: =IF(C4="","",IF(AND(AA4>=70,AC4="Cold"),"High-fit but cold",IF(AND(AA4<60,K4="Applied"),"Low-fit application",IF(AND(AA4>=70,OR(AC4="Named Contact",AC4="Outreach Logged")),"Targeted pursuit","Review"))))
B5: eBay | C5: Sr. Technical Program Manager | D5: Senior | E5: Canada | F5: Toronto | H5: Cold Portal | J5: No | K5: Rejected | L5: 46058 | M5: =IF(OR(L268="",A268=""),"",L268-A268) | P5: REJECTED 2026-02-05: eBay — "recruiting priorities have changed, no longer hiring for this role." Date Applied unknown — Elena to confirm. Distinct from row 141 (Sr. Technical Program Manager - R0074952, applied 8/14, still Applied) — different req. Retroactively logged 2026-09-12. | T5: =IF(G5="","",G5) | U5: =IF(C5="","",IF(OR(ISNUMBER(SEARCH("Director",C5)),ISNUMBER(SEARCH("Lead",C5)),ISNUMBER(SEARCH("Senior",C5)),ISNUMBER(SEARCH("Sr.",C5))),90,IF(OR(ISNUMBER(SEARCH("Manager",C5)),ISNUMBER(SEARCH("Program",C5)),ISNUMBER(SEARCH("Portfolio",C5))),80,60))) | V5: =IF(C5="","",IF(OR(ISNUMBER(SEARCH("AI",C5)),ISNUMBER(SEARCH("Data",C5)),ISNUMBER(SEARCH("Technology",C5)),ISNUMBER(SEARCH("Technical",C5)),ISNUMBER(SEARCH("Engineering",C5)),ISNUMBER(SEARCH("Platform",C5)),ISNUMBER(SEARCH("Portfolio",C5))),85,65)) | W5: =IF(C5="","",MIN(100,50+IF(S5<>"",25,0)+IF(R5<>"",15,0)+IF(P5<>"",10,0))) | X5: =IF(E5="","",IF(OR(E5="Canada",E5="CA"),100,IF(OR(E5="United States",E5="USA",E5="US"),IF(J5="Yes",45,75),65))) | Y5: =IF(C5="","",IF(OR(ISNUMBER(SEARCH("Program",C5)),ISNUMBER(SEARCH("Portfolio",C5)),ISNUMBER(SEARCH("Operations",C5)),ISNUMBER(SEARCH("Transformation",C5))),85,IF(ISNUMBER(SEARCH("Product Manager",C5)),55,70))) | Z5: =IF(C5="","",MIN(100,IF(I5<>"",60,10)+IF(AA5>0,MIN(40,AA5*20),0))) | AA5: =IF(T5="","",ROUND(T5*25%+U5*15%+V5*10%+W5*15%+X5*15%+Y5*10%+Z5*10%,0)) | AB5: =IF(AA5="","",IF(X5<50,"Selective / Barrier",IF(AA5>=80,"Tier 1 - Pursue",IF(AA5>=70,"Tier 2 - Pursue",IF(AA5>=60,"Tier 3 - Selective","Do Not Pursue"))))) | AC5: =IF(C5="","",IF(I5<>"","Named Contact",IF(AA5>0,"Outreach Logged","Cold"))) | AD5: =IF(B5="","",COUNTIF('Outreach Log'!$C:$C,B5)) | AE5: =IF(A5="","",IF(OR(K5="Rejected",K5="Closed"),IF(L5<>"",L5-A5,TODAY()-A5),TODAY()-A5)) | AF5: =IF(C5="","",IF(AND(AA5>=70,AC5="Cold"),"High-fit but cold",IF(AND(AA5<60,K5="Applied"),"Low-fit application",IF(AND(AA5>=70,OR(AC5="Named Contact",AC5="Outreach Logged")),"Targeted pursuit","Review"))))
B6: eBay | C6: Senior Design Program Manager | D6: Senior | E6: Canada | F6: Toronto | H6: Cold Portal | J6: No | K6: Rejected | L6: 46066 | M6: =IF(OR(L269="",A269=""),"",L269-A269) | P6: REJECTED 2026-02-13: eBay — "decided not to move forward." Date Applied unknown — Elena to confirm. Retroactively logged 2026-09-12. | T6: =IF(G6="","",G6) | U6: =IF(C6="","",IF(OR(ISNUMBER(SEARCH("Director",C6)),ISNUMBER(SEARCH("Lead",C6)),ISNUMBER(SEARCH("Senior",C6)),ISNUMBER(SEARCH("Sr.",C6))),90,IF(OR(ISNUMBER(SEARCH("Manager",C6)),ISNUMBER(SEARCH("Program",C6)),ISNUMBER(SEARCH("Portfolio",C6))),80,60))) | V6: =IF(C6="","",IF(OR(ISNUMBER(SEARCH("AI",C6)),ISNUMBER(SEARCH("Data",C6)),ISNUMBER(SEARCH("Technology",C6)),ISNUMBER(SEARCH("Technical",C6)),ISNUMBER(SEARCH("Engineering",C6)),ISNUMBER(SEARCH("Platform",C6)),ISNUMBER(SEARCH("Portfolio",C6))),85,65)) | W6: =IF(C6="","",MIN(100,50+IF(S6<>"",25,0)+IF(R6<>"",15,0)+IF(P6<>"",10,0))) | X6: =IF(E6="","",IF(OR(E6="Canada",E6="CA"),100,IF(OR(E6="United States",E6="USA",E6="US"),IF(J6="Yes",45,75),65))) | Y6: =IF(C6="","",IF(OR(ISNUMBER(SEARCH("Program",C6)),ISNUMBER(SEARCH("Portfolio",C6)),ISNUMBER(SEARCH("Operations",C6)),ISNUMBER(SEARCH("Transformation",C6))),85,IF(ISNUMBER(SEARCH("Product Manager",C6)),55,70))) | Z6: =IF(C6="","",MIN(100,IF(I6<>"",60,10)+IF(AA6>0,MIN(40,AA6*20),0))) | AA6: =IF(T6="","",ROUND(T6*25%+U6*15%+V6*10%+W6*15%+X6*15%+Y6*10%+Z6*10%,0)) | AB6: =IF(AA6="","",IF(X6<50,"Selective / Barrier",IF(AA6>=80,"Tier 1 - Pursue",IF(AA6>=70,"Tier 2 - Pursue",IF(AA6>=60,"Tier 3 - Selective","Do Not Pursue"))))) | AC6: =IF(C6="","",IF(I6<>"","Named Contact",IF(AA6>0,"Outreach Logged","Cold"))) | AD6: =IF(B6="","",COUNTIF('Outreach Log'!$C:$C,B6)) | AE6: =IF(A6="","",IF(OR(K6="Rejected",K6="Closed"),IF(L6<>"",L6-A6,TODAY()-A6),TODAY()-A6)) | AF6: =IF(C6="","",IF(AND(AA6>=70,AC6="Cold"),"High-fit but cold",IF(AND(AA6<60,K6="Applied"),"Low-fit application",IF(AND(AA6>=70,OR(AC6="Named Contact",AC6="Outreach Logged")),"Targeted pursuit","Review"))))
B7: eBay | C7: Senior Staff Design Program Manager | D7: Senior | E7: Canada | F7: Toronto | H7: Cold Portal | J7: No | K7: Rejected | L7: 46067 | M7: =IF(OR(L270="",A270=""),"",L270-A270) | P7: REJECTED 2026-02-14: eBay — "decided not to move forward." Date Applied unknown — Elena to confirm. Retroactively logged 2026-09-12. | T7: =IF(G7="","",G7) | U7: =IF(C7="","",IF(OR(ISNUMBER(SEARCH("Director",C7)),ISNUMBER(SEARCH("Lead",C7)),ISNUMBER(SEARCH("Senior",C7)),ISNUMBER(SEARCH("Sr.",C7))),90,IF(OR(ISNUMBER(SEARCH("Manager",C7)),ISNUMBER(SEARCH("Program",C7)),ISNUMBER(SEARCH("Portfolio",C7))),80,60))) | V7: =IF(C7="","",IF(OR(ISNUMBER(SEARCH("AI",C7)),ISNUMBER(SEARCH("Data",C7)),ISNUMBER(SEARCH("Technology",C7)),ISNUMBER(SEARCH("Technical",C7)),ISNUMBER(SEARCH("Engineering",C7)),ISNUMBER(SEARCH("Platform",C7)),ISNUMBER(SEARCH("Portfolio",C7))),85,65)) | W7: =IF(C7="","",MIN(100,50+IF(S7<>"",25,0)+IF(R7<>"",15,0)+IF(P7<>"",10,0))) | X7: =IF(E7="","",IF(OR(E7="Canada",E7="CA"),100,IF(OR(E7="United States",E7="USA",E7="US"),IF(J7="Yes",45,75),65))) | Y7: =IF(C7="","",IF(OR(ISNUMBER(SEARCH("Program",C7)),ISNUMBER(SEARCH("Portfolio",C7)),ISNUMBER(SEARCH("Operations",C7)),ISNUMBER(SEARCH("Transformation",C7))),85,IF(ISNUMBER(SEARCH("Product Manager",C7)),55,70))) | Z7: =IF(C7="","",MIN(100,IF(I7<>"",60,10)+IF(AA7>0,MIN(40,AA7*20),0))) | AA7: =IF(T7="","",ROUND(T7*25%+U7*15%+V7*10%+W7*15%+X7*15%+Y7*10%+Z7*10%,0)) | AB7: =IF(AA7="","",IF(X7<50,"Selective / Barrier",IF(AA7>=80,"Tier 1 - Pursue",IF(AA7>=70,"Tier 2 - Pursue",IF(AA7>=60,"Tier 3 - Selective","Do Not Pursue"))))) | AC7: =IF(C7="","",IF(I7<>"","Named Contact",IF(AA7>0,"Outreach Logged","Cold"))) | AD7: =IF(B7="","",COUNTIF('Outreach Log'!$C:$C,B7)) | AE7: =IF(A7="","",IF(OR(K7="Rejected",K7="Closed"),IF(L7<>"",L7-A7,TODAY()-A7),TODAY()-A7)) | AF7: =IF(C7="","",IF(AND(AA7>=70,AC7="Cold"),"High-fit but cold",IF(AND(AA7<60,K7="Applied"),"Low-fit application",IF(AND(AA7>=70,OR(AC7="Named Contact",AC7="Outreach Logged")),"Targeted pursuit","Review"))))
B8: eBay | C8: Sr.Tech Program Manager - Global Trust | D8: Senior | E8: Canada | F8: Toronto | H8: Cold Portal | J8: No | K8: Rejected | L8: 46074 | M8: =IF(OR(L271="",A271=""),"",L271-A271) | P8: REJECTED 2026-02-21: eBay — "decided not to move forward." Date Applied unknown — Elena to confirm. Retroactively logged 2026-09-12. | T8: =IF(G8="","",G8) | U8: =IF(C8="","",IF(OR(ISNUMBER(SEARCH("Director",C8)),ISNUMBER(SEARCH("Lead",C8)),ISNUMBER(SEARCH("Senior",C8)),ISNUMBER(SEARCH("Sr.",C8))),90,IF(OR(ISNUMBER(SEARCH("Manager",C8)),ISNUMBER(SEARCH("Program",C8)),ISNUMBER(SEARCH("Portfolio",C8))),80,60))) | V8: =IF(C8="","",IF(OR(ISNUMBER(SEARCH("AI",C8)),ISNUMBER(SEARCH("Data",C8)),ISNUMBER(SEARCH("Technology",C8)),ISNUMBER(SEARCH("Technical",C8)),ISNUMBER(SEARCH("Engineering",C8)),ISNUMBER(SEARCH("Platform",C8)),ISNUMBER(SEARCH("Portfolio",C8))),85,65)) | W8: =IF(C8="","",MIN(100,50+IF(S8<>"",25,0)+IF(R8<>"",15,0)+IF(P8<>"",10,0))) | X8: =IF(E8="","",IF(OR(E8="Canada",E8="CA"),100,IF(OR(E8="United States",E8="USA",E8="US"),IF(J8="Yes",45,75),65))) | Y8: =IF(C8="","",IF(OR(ISNUMBER(SEARCH("Program",C8)),ISNUMBER(SEARCH("Portfolio",C8)),ISNUMBER(SEARCH("Operations",C8)),ISNUMBER(SEARCH("Transformation",C8))),85,IF(ISNUMBER(SEARCH("Product Manager",C8)),55,70))) | Z8: =IF(C8="","",MIN(100,IF(I8<>"",60,10)+IF(AA8>0,MIN(40,AA8*20),0))) | AA8: =IF(T8="","",ROUND(T8*25%+U8*15%+V8*10%+W8*15%+X8*15%+Y8*10%+Z8*10%,0)) | AB8: =IF(AA8="","",IF(X8<50,"Selective / Barrier",IF(AA8>=80,"Tier 1 - Pursue",IF(AA8>=70,"Tier 2 - Pursue",IF(AA8>=60,"Tier 3 - Selective","Do Not Pursue"))))) | AC8: =IF(C8="","",IF(I8<>"","Named Contact",IF(AA8>0,"Outreach Logged","Cold"))) | AD8: =IF(B8="","",COUNTIF('Outreach Log'!$C:$C,B8)) | AE8: =IF(A8="","",IF(OR(K8="Rejected",K8="Closed"),IF(L8<>"",L8-A8,TODAY()-A8),TODAY()-A8)) | AF8: =IF(C8="","",IF(AND(AA8>=70,AC8="Cold"),"High-fit but cold",IF(AND(AA8<60,K8="Applied"),"Low-fit application",IF(AND(AA8>=70,OR(AC8="Named Contact",AC8="Outreach Logged")),"Targeted pursuit","Review"))))
B9: eBay | C9: Lead Technical Program Manager | D9: Lead | E9: Canada | F9: Toronto | H9: Cold Portal | J9: No | K9: Rejected | L9: 46087 | M9: =IF(OR(L272="",A272=""),"",L272-A272) | P9: REJECTED 2026-03-06: eBay — "recruiting priorities have changed, no longer hiring for this role." Date Applied unknown — Elena to confirm. First of two separate applications with this exact title (see also 4/25 rejection). Retroactively logged 2026-09-12. | T9: =IF(G9="","",G9) | U9: =IF(C9="","",IF(OR(ISNUMBER(SEARCH("Director",C9)),ISNUMBER(SEARCH("Lead",C9)),ISNUMBER(SEARCH("Senior",C9)),ISNUMBER(SEARCH("Sr.",C9))),90,IF(OR(ISNUMBER(SEARCH("Manager",C9)),ISNUMBER(SEARCH("Program",C9)),ISNUMBER(SEARCH("Portfolio",C9))),80,60))) | V9: =IF(C9="","",IF(OR(ISNUMBER(SEARCH("AI",C9)),ISNUMBER(SEARCH("Data",C9)),ISNUMBER(SEARCH("Technology",C9)),ISNUMBER(SEARCH("Technical",C9)),ISNUMBER(SEARCH("Engineering",C9)),ISNUMBER(SEARCH("Platform",C9)),ISNUMBER(SEARCH("Portfolio",C9))),85,65)) | W9: =IF(C9="","",MIN(100,50+IF(S9<>"",25,0)+IF(R9<>"",15,0)+IF(P9<>"",10,0))) | X9: =IF(E9="","",IF(OR(E9="Canada",E9="CA"),100,IF(OR(E9="United States",E9="USA",E9="US"),IF(J9="Yes",45,75),65))) | Y9: =IF(C9="","",IF(OR(ISNUMBER(SEARCH("Program",C9)),ISNUMBER(SEARCH("Portfolio",C9)),ISNUMBER(SEARCH("Operations",C9)),ISNUMBER(SEARCH("Transformation",C9))),85,IF(ISNUMBER(SEARCH("Product Manager",C9)),55,70))) | Z9: =IF(C9="","",MIN(100,IF(I9<>"",60,10)+IF(AA9>0,MIN(40,AA9*20),0))) | AA9: =IF(T9="","",ROUND(T9*25%+U9*15%+V9*10%+W9*15%+X9*15%+Y9*10%+Z9*10%,0)) | AB9: =IF(AA9="","",IF(X9<50,"Selective / Barrier",IF(AA9>=80,"Tier 1 - Pursue",IF(AA9>=70,"Tier 2 - Pursue",IF(AA9>=60,"Tier 3 - Selective","Do Not Pursue"))))) | AC9: =IF(C9="","",IF(I9<>"","Named Contact",IF(AA9>0,"Outreach Logged","Cold"))) | AD9: =IF(B9="","",COUNTIF('Outreach Log'!$C:$C,B9)) | AE9: =IF(A9="","",IF(OR(K9="Rejected",K9="Closed"),IF(L9<>"",L9-A9,TODAY()-A9),TODAY()-A9)) | AF9: =IF(C9="","",IF(AND(AA9>=70,AC9="Cold"),"High-fit but cold",IF(AND(AA9<60,K9="Applied"),"Low-fit application",IF(AND(AA9>=70,OR(AC9="Named Contact",AC9="Outreach Logged")),"Targeted pursuit","Review"))))
B10: eBay | C10: Senior RAI Program Manager | D10: Senior | E10: Canada | F10: Toronto | H10: Cold Portal | J10: No | K10: Rejected | L10: 46088 | M10: =IF(OR(L273="",A273=""),"",L273-A273) | P10: REJECTED 2026-03-07: eBay — "decided not to move forward." Date Applied unknown — Elena to confirm. Retroactively logged 2026-09-12. | T10: =IF(G10="","",G10) | U10: =IF(C10="","",IF(OR(ISNUMBER(SEARCH("Director",C10)),ISNUMBER(SEARCH("Lead",C10)),ISNUMBER(SEARCH("Senior",C10)),ISNUMBER(SEARCH("Sr.",C10))),90,IF(OR(ISNUMBER(SEARCH("Manager",C10)),ISNUMBER(SEARCH("Program",C10)),ISNUMBER(SEARCH("Portfolio",C10))),80,60))) | V10: =IF(C10="","",IF(OR(ISNUMBER(SEARCH("AI",C10)),ISNUMBER(SEARCH("Data",C10)),ISNUMBER(SEARCH("Technology",C10)),ISNUMBER(SEARCH("Technical",C10)),ISNUMBER(SEARCH("Engineering",C10)),ISNUMBER(SEARCH("Platform",C10)),ISNUMBER(SEARCH("Portfolio",C10))),85,65)) | W10: =IF(C10="","",MIN(100,50+IF(S10<>"",25,0)+IF(R10<>"",15,0)+IF(P10<>"",10,0))) | X10: =IF(E10="","",IF(OR(E10="Canada",E10="CA"),100,IF(OR(E10="United States",E10="USA",E10="US"),IF(J10="Yes",45,75),65))) | Y10: =IF(C10="","",IF(OR(ISNUMBER(SEARCH("Program",C10)),ISNUMBER(SEARCH("Portfolio",C10)),ISNUMBER(SEARCH("Operations",C10)),ISNUMBER(SEARCH("Transformation",C10))),85,IF(ISNUMBER(SEARCH("Product Manager",C10)),55,70))) | Z10: =IF(C10="","",MIN(100,IF(I10<>"",60,10)+IF(AA10>0,MIN(40,AA10*20),0))) | AA10: =IF(T10="","",ROUND(T10*25%+U10*15%+V10*10%+W10*15%+X10*15%+Y10*10%+Z10*10%,0)) | AB10: =IF(AA10="","",IF(X10<50,"Selective / Barrier",IF(AA10>=80,"Tier 1 - Pursue",IF(AA10>=70,"Tier 2 - Pursue",IF(AA10>=60,"Tier 3 - Selective","Do Not Pursue"))))) | AC10: =IF(C10="","",IF(I10<>"","Named Contact",IF(AA10>0,"Outreach Logged","Cold"))) | AD10: =IF(B10="","",COUNTIF('Outreach Log'!$C:$C,B10)) | AE10: =IF(A10="","",IF(OR(K10="Rejected",K10="Closed"),IF(L10<>"",L10-A10,TODAY()-A10),TODAY()-A10)) | AF10: =IF(C10="","",IF(AND(AA10>=70,AC10="Cold"),"High-fit but cold",IF(AND(AA10<60,K10="Applied"),"Low-fit application",IF(AND(AA10>=70,OR(AC10="Named Contact",AC10="Outreach Logged")),"Targeted pursuit","Review"))))
B11: eBay | C11: Senior Program Manager, Regulatory | D11: Senior | E11: Canada | F11: Toronto | H11: Cold Portal | J11: No | K11: Rejected | L11: 46114 | M11: =IF(OR(L274="",A274=""),"",L274-A274) | P11: REJECTED 2026-04-02: eBay — "decided not to move forward." Date Applied unknown — Elena to confirm. Retroactively logged 2026-09-12. | T11: =IF(G11="","",G11) | U11: =IF(C11="","",IF(OR(ISNUMBER(SEARCH("Director",C11)),ISNUMBER(SEARCH("Lead",C11)),ISNUMBER(SEARCH("Senior",C11)),ISNUMBER(SEARCH("Sr.",C11))),90,IF(OR(ISNUMBER(SEARCH("Manager",C11)),ISNUMBER(SEARCH("Program",C11)),ISNUMBER(SEARCH("Portfolio",C11))),80,60))) | V11: =IF(C11="","",IF(OR(ISNUMBER(SEARCH("AI",C11)),ISNUMBER(SEARCH("Data",C11)),ISNUMBER(SEARCH("Technology",C11)),ISNUMBER(SEARCH("Technical",C11)),ISNUMBER(SEARCH("Engineering",C11)),ISNUMBER(SEARCH("Platform",C11)),ISNUMBER(SEARCH("Portfolio",C11))),85,65)) | W11: =IF(C11="","",MIN(100,50+IF(S11<>"",25,0)+IF(R11<>"",15,0)+IF(P11<>"",10,0))) | X11: =IF(E11="","",IF(OR(E11="Canada",E11="CA"),100,IF(OR(E11="United States",E11="USA",E11="US"),IF(J11="Yes",45,75),65))) | Y11: =IF(C11="","",IF(OR(ISNUMBER(SEARCH("Program",C11)),ISNUMBER(SEARCH("Portfolio",C11)),ISNUMBER(SEARCH("Operations",C11)),ISNUMBER(SEARCH("Transformation",C11))),85,IF(ISNUMBER(SEARCH("Product Manager",C11)),55,70))) | Z11: =IF(C11="","",MIN(100,IF(I11<>"",60,10)+IF(AA11>0,MIN(40,AA11*20),0))) | AA11: =IF(T11="","",ROUND(T11*25%+U11*15%+V11*10%+W11*15%+X11*15%+Y11*10%+Z11*10%,0)) | AB11: =IF(AA11="","",IF(X11<50,"Selective / Barrier",IF(AA11>=80,"Tier 1 - Pursue",IF(AA11>=70,"Tier 2 - Pursue",IF(AA11>=60,"Tier 3 - Selective","Do Not Pursue"))))) | AC11: =IF(C11="","",IF(I11<>"","Named Contact",IF(AA11>0,"Outreach Logged","Cold"))) | AD11: =IF(B11="","",COUNTIF('Outreach Log'!$C:$C,B11)) | AE11: =IF(A11="","",IF(OR(K11="Rejected",K11="Closed"),IF(L11<>"",L11-A11,TODAY()-A11),TODAY()-A11)) | AF11: =IF(C11="","",IF(AND(AA11>=70,AC11="Cold"),"High-fit but cold",IF(AND(AA11<60,K11="Applied"),"Low-fit application",IF(AND(AA11>=70,OR(AC11="Named Contact",AC11="Outreach Logged")),"Targeted pursuit","Review"))))
B12: eBay | C12: Business Operations and Planning Manager | D12: Manager | E12: Canada | F12: Toronto | H12: Cold Portal | J12: No | K12: Rejected | L12: 46133 | M12: =IF(OR(L275="",A275=""),"",L275-A275) | P12: REJECTED 2026-04-21: eBay — "decided not to move forward." Date Applied unknown — Elena to confirm. Retroactively logged 2026-09-12. | T12: =IF(G12="","",G12) | U12: =IF(C12="","",IF(OR(ISNUMBER(SEARCH("Director",C12)),ISNUMBER(SEARCH("Lead",C12)),ISNUMBER(SEARCH("Senior",C12)),ISNUMBER(SEARCH("Sr.",C12))),90,IF(OR(ISNUMBER(SEARCH("Manager",C12)),ISNUMBER(SEARCH("Program",C12)),ISNUMBER(SEARCH("Portfolio",C12))),80,60))) | V12: =IF(C12="","",IF(OR(ISNUMBER(SEARCH("AI",C12)),ISNUMBER(SEARCH("Data",C12)),ISNUMBER(SEARCH("Technology",C12)),ISNUMBER(SEARCH("Technical",C12)),ISNUMBER(SEARCH("Engineering",C12)),ISNUMBER(SEARCH("Platform",C12)),ISNUMBER(SEARCH("Portfolio",C12))),85,65)) | W12: =IF(C12="","",MIN(100,50+IF(S12<>"",25,0)+IF(R12<>"",15,0)+IF(P12<>"",10,0))) | X12: =IF(E12="","",IF(OR(E12="Canada",E12="CA"),100,IF(OR(E12="United States",E12="USA",E12="US"),IF(J12="Yes",45,75),65))) | Y12: =IF(C12="","",IF(OR(ISNUMBER(SEARCH("Program",C12)),ISNUMBER(SEARCH("Portfolio",C12)),ISNUMBER(SEARCH("Operations",C12)),ISNUMBER(SEARCH("Transformation",C12))),85,IF(ISNUMBER(SEARCH("Product Manager",C12)),55,70))) | Z12: =IF(C12="","",MIN(100,IF(I12<>"",60,10)+IF(AA12>0,MIN(40,AA12*20),0))) | AA12: =IF(T12="","",ROUND(T12*25%+U12*15%+V12*10%+W12*15%+X12*15%+Y12*10%+Z12*10%,0)) | AB12: =IF(AA12="","",IF(X12<50,"Selective / Barrier",IF(AA12>=80,"Tier 1 - Pursue",IF(AA12>=70,"Tier 2 - Pursue",IF(AA12>=60,"Tier 3 - Selective","Do Not Pursue"))))) | AC12: =IF(C12="","",IF(I12<>"","Named Contact",IF(AA12>0,"Outreach Logged","Cold"))) | AD12: =IF(B12="","",COUNTIF('Outreach Log'!$C:$C,B12)) | AE12: =IF(A12="","",IF(OR(K12="Rejected",K12="Closed"),IF(L12<>"",L12-A12,TODAY()-A12),TODAY()-A12)) | AF12: =IF(C12="","",IF(AND(AA12>=70,AC12="Cold"),"High-fit but cold",IF(AND(AA12<60,K12="Applied"),"Low-fit application",IF(AND(AA12>=70,OR(AC12="Named Contact",AC12="Outreach Logged")),"Targeted pursuit","Review"))))
B13: eBay | C13: Lead Technical Program Manager (2nd application) | D13: Lead | E13: Canada | F13: Toronto | H13: Cold Portal | J13: No | K13: Rejected | L13: 46137 | M13: =IF(OR(L276="",A276=""),"",L276-A276) | P13: REJECTED 2026-04-25: eBay — "decided not to move forward." Date Applied unknown — Elena to confirm. Second, separate application with this exact title (see also 3/6 rejection — different req). Retroactively logged 2026-09-12. | T13: =IF(G13="","",G13) | U13: =IF(C13="","",IF(OR(ISNUMBER(SEARCH("Director",C13)),ISNUMBER(SEARCH("Lead",C13)),ISNUMBER(SEARCH("Senior",C13)),ISNUMBER(SEARCH("Sr.",C13))),90,IF(OR(ISNUMBER(SEARCH("Manager",C13)),ISNUMBER(SEARCH("Program",C13)),ISNUMBER(SEARCH("Portfolio",C13))),80,60))) | V13: =IF(C13="","",IF(OR(ISNUMBER(SEARCH("AI",C13)),ISNUMBER(SEARCH("Data",C13)),ISNUMBER(SEARCH("Technology",C13)),ISNUMBER(SEARCH("Technical",C13)),ISNUMBER(SEARCH("Engineering",C13)),ISNUMBER(SEARCH("Platform",C13)),ISNUMBER(SEARCH("Portfolio",C13))),85,65)) | W13: =IF(C13="","",MIN(100,50+IF(S13<>"",25,0)+IF(R13<>"",15,0)+IF(P13<>"",10,0))) | X13: =IF(E13="","",IF(OR(E13="Canada",E13="CA"),100,IF(OR(E13="United States",E13="USA",E13="US"),IF(J13="Yes",45,75),65))) | Y13: =IF(C13="","",IF(OR(ISNUMBER(SEARCH("Program",C13)),ISNUMBER(SEARCH("Portfolio",C13)),ISNUMBER(SEARCH("Operations",C13)),ISNUMBER(SEARCH("Transformation",C13))),85,IF(ISNUMBER(SEARCH("Product Manager",C13)),55,70))) | Z13: =IF(C13="","",MIN(100,IF(I13<>"",60,10)+IF(AA13>0,MIN(40,AA13*20),0))) | AA13: =IF(T13="","",ROUND(T13*25%+U13*15%+V13*10%+W13*15%+X13*15%+Y13*10%+Z13*10%,0)) | AB13: =IF(AA13="","",IF(X13<50,"Selective / Barrier",IF(AA13>=80,"Tier 1 - Pursue",IF(AA13>=70,"Tier 2 - Pursue",IF(AA13>=60,"Tier 3 - Selective","Do Not Pursue"))))) | AC13: =IF(C13="","",IF(I13<>"","Named Contact",IF(AA13>0,"Outreach Logged","Cold"))) | AD13: =IF(B13="","",COUNTIF('Outreach Log'!$C:$C,B13)) | AE13: =IF(A13="","",IF(OR(K13="Rejected",K13="Closed"),IF(L13<>"",L13-A13,TODAY()-A13),TODAY()-A13)) | AF13: =IF(C13="","",IF(AND(AA13>=70,AC13="Cold"),"High-fit but cold",IF(AND(AA13<60,K13="Applied"),"Low-fit application",IF(AND(AA13>=70,OR(AC13="Named Contact",AC13="Outreach Logged")),"Targeted pursuit","Review"))))
B14: eBay | C14: Director of Strategic Programs | D14: Director | E14: Canada | F14: Toronto | H14: Cold Portal | J14: No | K14: Rejected | L14: 46141 | M14: =IF(OR(L277="",A277=""),"",L277-A277) | P14: REJECTED 2026-04-29: eBay — "decided not to move forward." Date Applied unknown — Elena to confirm. Retroactively logged 2026-09-12. | T14: =IF(G14="","",G14) | U14: =IF(C14="","",IF(OR(ISNUMBER(SEARCH("Director",C14)),ISNUMBER(SEARCH("Lead",C14)),ISNUMBER(SEARCH("Senior",C14)),ISNUMBER(SEARCH("Sr.",C14))),90,IF(OR(ISNUMBER(SEARCH("Manager",C14)),ISNUMBER(SEARCH("Program",C14)),ISNUMBER(SEARCH("Portfolio",C14))),80,60))) | V14: =IF(C14="","",IF(OR(ISNUMBER(SEARCH("AI",C14)),ISNUMBER(SEARCH("Data",C14)),ISNUMBER(SEARCH("Technology",C14)),ISNUMBER(SEARCH("Technical",C14)),ISNUMBER(SEARCH("Engineering",C14)),ISNUMBER(SEARCH("Platform",C14)),ISNUMBER(SEARCH("Portfolio",C14))),85,65)) | W14: =IF(C14="","",MIN(100,50+IF(S14<>"",25,0)+IF(R14<>"",15,0)+IF(P14<>"",10,0))) | X14: =IF(E14="","",IF(OR(E14="Canada",E14="CA"),100,IF(OR(E14="United States",E14="USA",E14="US"),IF(J14="Yes",45,75),65))) | Y14: =IF(C14="","",IF(OR(ISNUMBER(SEARCH("Program",C14)),ISNUMBER(SEARCH("Portfolio",C14)),ISNUMBER(SEARCH("Operations",C14)),ISNUMBER(SEARCH("Transformation",C14))),85,IF(ISNUMBER(SEARCH("Product Manager",C14)),55,70))) | Z14: =IF(C14="","",MIN(100,IF(I14<>"",60,10)+IF(AA14>0,MIN(40,AA14*20),0))) | AA14: =IF(T14="","",ROUND(T14*25%+U14*15%+V14*10%+W14*15%+X14*15%+Y14*10%+Z14*10%,0)) | AB14: =IF(AA14="","",IF(X14<50,"Selective / Barrier",IF(AA14>=80,"Tier 1 - Pursue",IF(AA14>=70,"Tier 2 - Pursue",IF(AA14>=60,"Tier 3 - Selective","Do Not Pursue"))))) | AC14: =IF(C14="","",IF(I14<>"","Named Contact",IF(AA14>0,"Outreach Logged","Cold"))) | AD14: =IF(B14="","",COUNTIF('Outreach Log'!$C:$C,B14)) | AE14: =IF(A14="","",IF(OR(K14="Rejected",K14="Closed"),IF(L14<>"",L14-A14,TODAY()-A14),TODAY()-A14)) | AF14: =IF(C14="","",IF(AND(AA14>=70,AC14="Cold"),"High-fit but cold",IF(AND(AA14<60,K14="Applied"),"Low-fit application",IF(AND(AA14>=70,OR(AC14="Named Contact",AC14="Outreach Logged")),"Targeted pursuit","Review"))))
B15: eBay | C15: Sr. Engineering Program Manager | D15: Senior | E15: Canada | F15: Toronto | H15: Cold Portal | J15: No | K15: Rejected | L15: 46221 | M15: =IF(OR(L278="",A278=""),"",L278-A278) | P15: Advanced to next recruiting stage 2026-06-17 ("thrilled to invite you to the next stage"). REJECTED 2026-07-18: eBay — "decided not to move forward." Date Applied unknown — Elena to confirm. Distinct from row 38 (Director, AI Workflow Transformation, applied 7/5). Retroactively logged 2026-09-12. | Q15: 46190 | T15: =IF(G15="","",G15) | U15: =IF(C15="","",IF(OR(ISNUMBER(SEARCH("Director",C15)),ISNUMBER(SEARCH("Lead",C15)),ISNUMBER(SEARCH("Senior",C15)),ISNUMBER(SEARCH("Sr.",C15))),90,IF(OR(ISNUMBER(SEARCH("Manager",C15)),ISNUMBER(SEARCH("Program",C15)),ISNUMBER(SEARCH("Portfolio",C15))),80,60))) | V15: =IF(C15="","",IF(OR(ISNUMBER(SEARCH("AI",C15)),ISNUMBER(SEARCH("Data",C15)),ISNUMBER(SEARCH("Technology",C15)),ISNUMBER(SEARCH("Technical",C15)),ISNUMBER(SEARCH("Engineering",C15)),ISNUMBER(SEARCH("Platform",C15)),ISNUMBER(SEARCH("Portfolio",C15))),85,65)) | W15: =IF(C15="","",MIN(100,50+IF(S15<>"",25,0)+IF(R15<>"",15,0)+IF(P15<>"",10,0))) | X15: =IF(E15="","",IF(OR(E15="Canada",E15="CA"),100,IF(OR(E15="United States",E15="USA",E15="US"),IF(J15="Yes",45,75),65))) | Y15: =IF(C15="","",IF(OR(ISNUMBER(SEARCH("Program",C15)),ISNUMBER(SEARCH("Portfolio",C15)),ISNUMBER(SEARCH("Operations",C15)),ISNUMBER(SEARCH("Transformation",C15))),85,IF(ISNUMBER(SEARCH("Product Manager",C15)),55,70))) | Z15: =IF(C15="","",MIN(100,IF(I15<>"",60,10)+IF(AA15>0,MIN(40,AA15*20),0))) | AA15: =IF(T15="","",ROUND(T15*25%+U15*15%+V15*10%+W15*15%+X15*15%+Y15*10%+Z15*10%,0)) | AB15: =IF(AA15="","",IF(X15<50,"Selective / Barrier",IF(AA15>=80,"Tier 1 - Pursue",IF(AA15>=70,"Tier 2 - Pursue",IF(AA15>=60,"Tier 3 - Selective","Do Not Pursue"))))) | AC15: =IF(C15="","",IF(I15<>"","Named Contact",IF(AA15>0,"Outreach Logged","Cold"))) | AD15: =IF(B15="","",COUNTIF('Outreach Log'!$C:$C,B15)) | AE15: =IF(A15="","",IF(OR(K15="Rejected",K15="Closed"),IF(L15<>"",L15-A15,TODAY()-A15),TODAY()-A15)) | AF15: =IF(C15="","",IF(AND(AA15>=70,AC15="Cold"),"High-fit but cold",IF(AND(AA15<60,K15="Applied"),"Low-fit application",IF(AND(AA15>=70,OR(AC15="Named Contact",AC15="Outreach Logged")),"Targeted pursuit","Review"))))
B16: eBay | C16: Product Manager, Seller Experience | D16: Manager | E16: Canada | F16: Toronto | H16: Cold Portal | J16: No | K16: Rejected | L16: 46225 | M16: =IF(OR(L279="",A279=""),"",L279-A279) | P16: REJECTED 2026-07-22: eBay — "decided not to move forward." Date Applied unknown — Elena to confirm. Retroactively logged 2026-09-12. | T16: =IF(G16="","",G16) | U16: =IF(C16="","",IF(OR(ISNUMBER(SEARCH("Director",C16)),ISNUMBER(SEARCH("Lead",C16)),ISNUMBER(SEARCH("Senior",C16)),ISNUMBER(SEARCH("Sr.",C16))),90,IF(OR(ISNUMBER(SEARCH("Manager",C16)),ISNUMBER(SEARCH("Program",C16)),ISNUMBER(SEARCH("Portfolio",C16))),80,60))) | V16: =IF(C16="","",IF(OR(ISNUMBER(SEARCH("AI",C16)),ISNUMBER(SEARCH("Data",C16)),ISNUMBER(SEARCH("Technology",C16)),ISNUMBER(SEARCH("Technical",C16)),ISNUMBER(SEARCH("Engineering",C16)),ISNUMBER(SEARCH("Platform",C16)),ISNUMBER(SEARCH("Portfolio",C16))),85,65)) | W16: =IF(C16="","",MIN(100,50+IF(S16<>"",25,0)+IF(R16<>"",15,0)+IF(P16<>"",10,0))) | X16: =IF(E16="","",IF(OR(E16="Canada",E16="CA"),100,IF(OR(E16="United States",E16="USA",E16="US"),IF(J16="Yes",45,75),65))) | Y16: =IF(C16="","",IF(OR(ISNUMBER(SEARCH("Program",C16)),ISNUMBER(SEARCH("Portfolio",C16)),ISNUMBER(SEARCH("Operations",C16)),ISNUMBER(SEARCH("Transformation",C16))),85,IF(ISNUMBER(SEARCH("Product Manager",C16)),55,70))) | Z16: =IF(C16="","",MIN(100,IF(I16<>"",60,10)+IF(AA16>0,MIN(40,AA16*20),0))) | AA16: =IF(T16="","",ROUND(T16*25%+U16*15%+V16*10%+W16*15%+X16*15%+Y16*10%+Z16*10%,0)) | AB16: =IF(AA16="","",IF(X16<50,"Selective / Barrier",IF(AA16>=80,"Tier 1 - Pursue",IF(AA16>=70,"Tier 2 - Pursue",IF(AA16>=60,"Tier 3 - Selective","Do Not Pursue"))))) | AC16: =IF(C16="","",IF(I16<>"","Named Contact",IF(AA16>0,"Outreach Logged","Cold"))) | AD16: =IF(B16="","",COUNTIF('Outreach Log'!$C:$C,B16)) | AE16: =IF(A16="","",IF(OR(K16="Rejected",K16="Closed"),IF(L16<>"",L16-A16,TODAY()-A16),TODAY()-A16)) | AF16: =IF(C16="","",IF(AND(AA16>=70,AC16="Cold"),"High-fit but cold",IF(AND(AA16<60,K16="Applied"),"Low-fit application",IF(AND(AA16>=70,OR(AC16="Named Contact",AC16="Outreach Logged")),"Targeted pursuit","Review"))))
B17: OMERS / Oxford Properties | C17: Project Delivery Lead (14-Month Contract) | D17: Manager | E17: Canada | F17: Toronto | H17: Cold Portal | J17: No | K17: Rejected | L17: 46027 | M17: =IF(OR(L280="",A280=""),"",L280-A280) | P17: REJECTED 2026-01-05: OMERS/Oxford Properties (recruiting@jobalerts.omers.com) — "we have decided to pursue other candidates whose qualifications and experience are more in line with the position requirements." Date Applied: January 2026 (exact day unknown, confirmed by Elena). Distinct from row 163 (Program Manager, Program Management & Delivery, D&T CSI, applied 8/21) — separate application. Retroactively logged via Gmail screenshot review 2026-09-13. | T17: =IF(G17="","",G17) | U17: =IF(C17="","",IF(OR(ISNUMBER(SEARCH("Director",C17)),ISNUMBER(SEARCH("Lead",C17)),ISNUMBER(SEARCH("Senior",C17)),ISNUMBER(SEARCH("Sr.",C17))),90,IF(OR(ISNUMBER(SEARCH("Manager",C17)),ISNUMBER(SEARCH("Program",C17)),ISNUMBER(SEARCH("Portfolio",C17))),80,60))) | V17: =IF(C17="","",IF(OR(ISNUMBER(SEARCH("AI",C17)),ISNUMBER(SEARCH("Data",C17)),ISNUMBER(SEARCH("Technology",C17)),ISNUMBER(SEARCH("Technical",C17)),ISNUMBER(SEARCH("Engineering",C17)),ISNUMBER(SEARCH("Platform",C17)),ISNUMBER(SEARCH("Portfolio",C17))),85,65)) | W17: =IF(C17="","",MIN(100,50+IF(S17<>"",25,0)+IF(R17<>"",15,0)+IF(P17<>"",10,0))) | X17: =IF(E17="","",IF(OR(E17="Canada",E17="CA"),100,IF(OR(E17="United States",E17="USA",E17="US"),IF(J17="Yes",45,75),65))) | Y17: =IF(C17="","",IF(OR(ISNUMBER(SEARCH("Program",C17)),ISNUMBER(SEARCH("Portfolio",C17)),ISNUMBER(SEARCH("Operations",C17)),ISNUMBER(SEARCH("Transformation",C17))),85,IF(ISNUMBER(SEARCH("Product Manager",C17)),55,70))) | Z17: =IF(C17="","",MIN(100,IF(I17<>"",60,10)+IF(AA17>0,MIN(40,AA17*20),0))) | AA17: =IF(T17="","",ROUND(T17*25%+U17*15%+V17*10%+W17*15%+X17*15%+Y17*10%+Z17*10%,0)) | AB17: =IF(AA17="","",IF(X17<50,"Selective / Barrier",IF(AA17>=80,"Tier 1 - Pursue",IF(AA17>=70,"Tier 2 - Pursue",IF(AA17>=60,"Tier 3 - Selective","Do Not Pursue"))))) | AC17: =IF(C17="","",IF(I17<>"","Named Contact",IF(AA17>0,"Outreach Logged","Cold"))) | AD17: =IF(B17="","",COUNTIF('Outreach Log'!$C:$C,B17)) | AE17: =IF(A17="","",IF(OR(K17="Rejected",K17="Closed"),IF(L17<>"",L17-A17,TODAY()-A17),TODAY()-A17)) | AF17: =IF(C17="","",IF(AND(AA17>=70,AC17="Cold"),"High-fit but cold",IF(AND(AA17<60,K17="Applied"),"Low-fit application",IF(AND(AA17>=70,OR(AC17="Named Contact",AC17="Outreach Logged")),"Targeted pursuit","Review"))))
B18: eBay | C18: Sr. Product Mgr, Live Personalization | D18: Senior | E18: Canada | F18: Toronto | G18: 45 | H18: Cold Portal | J18: No | K18: Rejected | L18: 46279 | M18: =IF(OR(L281="",A281=""),"",L281-A281) | P18: REJECTED 2026-09-14: eBay Talent Acquisition Team — "recruiting priorities have changed, no longer hiring for this role." Date Applied unknown — Elena to confirm. Distinct from all other eBay Product Manager roles already logged (e.g. Sr. Product Manager, Search AI). Est. fit score: 45 — Product Manager title (not Program Manager), lower overlap with her core delivery/portfolio management track; personalization/product-feature domain is further from her direct experience. | T18: =IF(G18="","",G18) | U18: =IF(C18="","",IF(OR(ISNUMBER(SEARCH("Director",C18)),ISNUMBER(SEARCH("Lead",C18)),ISNUMBER(SEARCH("Senior",C18)),ISNUMBER(SEARCH("Sr.",C18))),90,IF(OR(ISNUMBER(SEARCH("Manager",C18)),ISNUMBER(SEARCH("Program",C18)),ISNUMBER(SEARCH("Portfolio",C18))),80,60))) | V18: =IF(C18="","",IF(OR(ISNUMBER(SEARCH("AI",C18)),ISNUMBER(SEARCH("Data",C18)),ISNUMBER(SEARCH("Technology",C18)),ISNUMBER(SEARCH("Technical",C18)),ISNUMBER(SEARCH("Engineering",C18)),ISNUMBER(SEARCH("Platform",C18)),ISNUMBER(SEARCH("Portfolio",C18))),85,65)) | W18: =IF(C18="","",MIN(100,50+IF(S18<>"",25,0)+IF(R18<>"",15,0)+IF(P18<>"",10,0))) | X18: =IF(E18="","",IF(OR(E18="Canada",E18="CA"),100,IF(OR(E18="United States",E18="USA",E18="US"),IF(J18="Yes",45,75),65))) | Y18: =IF(C18="","",IF(OR(ISNUMBER(SEARCH("Program",C18)),ISNUMBER(SEARCH("Portfolio",C18)),ISNUMBER(SEARCH("Operations",C18)),ISNUMBER(SEARCH("Transformation",C18))),85,IF(ISNUMBER(SEARCH("Product Manager",C18)),55,70))) | Z18: =IF(C18="","",MIN(100,IF(I18<>"",60,10)+IF(AA18>0,MIN(40,AA18*20),0))) | AA18: =IF(T18="","",ROUND(T18*25%+U18*15%+V18*10%+W18*15%+X18*15%+Y18*10%+Z18*10%,0)) | AB18: =IF(AA18="","",IF(X18<50,"Selective / Barrier",IF(AA18>=80,"Tier 1 - Pursue",IF(AA18>=70,"Tier 2 - Pursue",IF(AA18>=60,"Tier 3 - Selective","Do Not Pursue"))))) | AC18: =IF(C18="","",IF(I18<>"","Named Contact",IF(AA18>0,"Outreach Logged","Cold"))) | AD18: =IF(B18="","",COUNTIF('Outreach Log'!$C:$C,B18)) | AE18: =IF(A18="","",IF(OR(K18="Rejected",K18="Closed"),IF(L18<>"",L18-A18,TODAY()-A18),TODAY()-A18)) | AF18: =IF(C18="","",IF(AND(AA18>=70,AC18="Cold"),"High-fit but cold",IF(AND(AA18<60,K18="Applied"),"Low-fit application",IF(AND(AA18>=70,OR(AC18="Named Contact",AC18="Outreach Logged")),"Targeted pursuit","Review"))))
B19: OMERS / Oxford Properties | C19: Associate Director, AI Process Engineering (12 Months Contract) | D19: Assoc Director | E19: Canada | F19: Toronto | G19: 72 | H19: Cold Portal | J19: No | K19: Rejected | L19: 46085 | M19: =IF(OR(L282="",A282=""),"",L282-A282) | P19: REJECTED 2026-03-04: OMERS/Oxford Properties (recruiting@jobalerts.omers.com) — "decided to pursue other candidates whose qualifications and experience are more in line with the position requirements." Date Applied unknown — Elena to confirm. Third, distinct OMERS/Oxford Properties application — separate from Project Delivery Lead (rejected Jan) and Program Manager, D&T CSI (still Applied, applied 8/21). Retroactively logged via Gmail review 2026-09-15. Est. fit score: 72 — AI Process Engineering aligns with her Bell Data & AI portfolio and process-governance track record. | T19: =IF(G19="","",G19) | U19: =IF(C19="","",IF(OR(ISNUMBER(SEARCH("Director",C19)),ISNUMBER(SEARCH("Lead",C19)),ISNUMBER(SEARCH("Senior",C19)),ISNUMBER(SEARCH("Sr.",C19))),90,IF(OR(ISNUMBER(SEARCH("Manager",C19)),ISNUMBER(SEARCH("Program",C19)),ISNUMBER(SEARCH("Portfolio",C19))),80,60))) | V19: =IF(C19="","",IF(OR(ISNUMBER(SEARCH("AI",C19)),ISNUMBER(SEARCH("Data",C19)),ISNUMBER(SEARCH("Technology",C19)),ISNUMBER(SEARCH("Technical",C19)),ISNUMBER(SEARCH("Engineering",C19)),ISNUMBER(SEARCH("Platform",C19)),ISNUMBER(SEARCH("Portfolio",C19))),85,65)) | W19: =IF(C19="","",MIN(100,50+IF(S19<>"",25,0)+IF(R19<>"",15,0)+IF(P19<>"",10,0))) | X19: =IF(E19="","",IF(OR(E19="Canada",E19="CA"),100,IF(OR(E19="United States",E19="USA",E19="US"),IF(J19="Yes",45,75),65))) | Y19: =IF(C19="","",IF(OR(ISNUMBER(SEARCH("Program",C19)),ISNUMBER(SEARCH("Portfolio",C19)),ISNUMBER(SEARCH("Operations",C19)),ISNUMBER(SEARCH("Transformation",C19))),85,IF(ISNUMBER(SEARCH("Product Manager",C19)),55,70))) | Z19: =IF(C19="","",MIN(100,IF(I19<>"",60,10)+IF(AA19>0,MIN(40,AA19*20),0))) | AA19: =IF(T19="","",ROUND(T19*25%+U19*15%+V19*10%+W19*15%+X19*15%+Y19*10%+Z19*10%,0)) | AB19: =IF(AA19="","",IF(X19<50,"Selective / Barrier",IF(AA19>=80,"Tier 1 - Pursue",IF(AA19>=70,"Tier 2 - Pursue",IF(AA19>=60,"Tier 3 - Selective","Do Not Pursue"))))) | AC19: =IF(C19="","",IF(I19<>"","Named Contact",IF(AA19>0,"Outreach Logged","Cold"))) | AD19: =IF(B19="","",COUNTIF('Outreach Log'!$C:$C,B19)) | AE19: =IF(A19="","",IF(OR(K19="Rejected",K19="Closed"),IF(L19<>"",L19-A19,TODAY()-A19),TODAY()-A19)) | AF19: =IF(C19="","",IF(AND(AA19>=70,AC19="Cold"),"High-fit but cold",IF(AND(AA19<60,K19="Applied"),"Low-fit application",IF(AND(AA19>=70,OR(AC19="Named Contact",AC19="Outreach Logged")),"Targeted pursuit","Review"))))
B20: Equifax | C20: Head of Enterprise Project Management Office (EPMO) | D20: Director | E20: Canada | F20: Toronto | G20: 82 | H20: Cold Portal | J20: No | K20: Rejected | L20: 46192 | M20: =IF(OR(L283="",A283=""),"",L283-A283) | P20: Applied date unknown (likely March/early April 2026) — Elena to confirm. Interviewed by phone ~2026-04-24 with Christy Tillich (Manager, Talent Acquisition); Elena's own 2026-05-11 follow-up confirms she received an email that she was "moving to the next stage." REJECTED 2026-06-19: "after further review... decided to move forward with other candidates." Retroactively logged via Gmail review 2026-09-18 — was missing from tracker entirely. Est. fit score: 82 — Head of EPMO (Director-level) is a very strong title match to her core portfolio/PMO leadership lane. | Q20: 46136 | T20: =IF(G20="","",G20) | U20: =IF(C20="","",IF(OR(ISNUMBER(SEARCH("Director",C20)),ISNUMBER(SEARCH("Lead",C20)),ISNUMBER(SEARCH("Senior",C20)),ISNUMBER(SEARCH("Sr.",C20))),90,IF(OR(ISNUMBER(SEARCH("Manager",C20)),ISNUMBER(SEARCH("Program",C20)),ISNUMBER(SEARCH("Portfolio",C20))),80,60))) | V20: =IF(C20="","",IF(OR(ISNUMBER(SEARCH("AI",C20)),ISNUMBER(SEARCH("Data",C20)),ISNUMBER(SEARCH("Technology",C20)),ISNUMBER(SEARCH("Technical",C20)),ISNUMBER(SEARCH("Engineering",C20)),ISNUMBER(SEARCH("Platform",C20)),ISNUMBER(SEARCH("Portfolio",C20))),85,65)) | W20: =IF(C20="","",MIN(100,50+IF(S20<>"",25,0)+IF(R20<>"",15,0)+IF(P20<>"",10,0))) | X20: =IF(E20="","",IF(OR(E20="Canada",E20="CA"),100,IF(OR(E20="United States",E20="USA",E20="US"),IF(J20="Yes",45,75),65))) | Y20: =IF(C20="","",IF(OR(ISNUMBER(SEARCH("Program",C20)),ISNUMBER(SEARCH("Portfolio",C20)),ISNUMBER(SEARCH("Operations",C20)),ISNUMBER(SEARCH("Transformation",C20))),85,IF(ISNUMBER(SEARCH("Product Manager",C20)),55,70))) | Z20: =IF(C20="","",MIN(100,IF(I20<>"",60,10)+IF(AA20>0,MIN(40,AA20*20),0))) | AA20: =IF(T20="","",ROUND(T20*25%+U20*15%+V20*10%+W20*15%+X20*15%+Y20*10%+Z20*10%,0)) | AB20: =IF(AA20="","",IF(X20<50,"Selective / Barrier",IF(AA20>=80,"Tier 1 - Pursue",IF(AA20>=70,"Tier 2 - Pursue",IF(AA20>=60,"Tier 3 - Selective","Do Not Pursue"))))) | AC20: =IF(C20="","",IF(I20<>"","Named Contact",IF(AA20>0,"Outreach Logged","Cold"))) | AD20: =IF(B20="","",COUNTIF('Outreach Log'!$C:$C,B20)) | AE20: =IF(A20="","",IF(OR(K20="Rejected",K20="Closed"),IF(L20<>"",L20-A20,TODAY()-A20),TODAY()-A20)) | AF20: =IF(C20="","",IF(AND(AA20>=70,AC20="Cold"),"High-fit but cold",IF(AND(AA20<60,K20="Applied"),"Low-fit application",IF(AND(AA20>=70,OR(AC20="Named Contact",AC20="Outreach Logged")),"Targeted pursuit","Review"))))
B21: OLG (Ontario Lottery and Gaming Corporation) | C21: Senior IT Portfolio Operations Manager (Req R26_00102) | D21: Senior | E21: Canada | F21: Toronto | G21: 78 | H21: Recruiter (IT-IQ agency) | J21: No | K21: Rejected | L21: 46101 | M21: =IF(OR(L284="",A284=""),"",L284-A284) | P21: Applied date unknown (via IT-IQ agency, Sahand Sadr) — Elena to confirm. Virtual interview held 2026-03-05 with Meghayu Dave (OLG). REJECTED 2026-03-20: "we have hired a successful candidate and the role is closed now" — Elena noted this was never communicated to her directly until she followed up. Retroactively logged via Gmail review 2026-09-18 — was missing from tracker entirely. Est. fit score: 78 — Senior IT Portfolio Operations Manager is a strong title match to her core portfolio-management lane. | Q21: 46086 | T21: =IF(G21="","",G21) | U21: =IF(C21="","",IF(OR(ISNUMBER(SEARCH("Director",C21)),ISNUMBER(SEARCH("Lead",C21)),ISNUMBER(SEARCH("Senior",C21)),ISNUMBER(SEARCH("Sr.",C21))),90,IF(OR(ISNUMBER(SEARCH("Manager",C21)),ISNUMBER(SEARCH("Program",C21)),ISNUMBER(SEARCH("Portfolio",C21))),80,60))) | V21: =IF(C21="","",IF(OR(ISNUMBER(SEARCH("AI",C21)),ISNUMBER(SEARCH("Data",C21)),ISNUMBER(SEARCH("Technology",C21)),ISNUMBER(SEARCH("Technical",C21)),ISNUMBER(SEARCH("Engineering",C21)),ISNUMBER(SEARCH("Platform",C21)),ISNUMBER(SEARCH("Portfolio",C21))),85,65)) | W21: =IF(C21="","",MIN(100,50+IF(S21<>"",25,0)+IF(R21<>"",15,0)+IF(P21<>"",10,0))) | X21: =IF(E21="","",IF(OR(E21="Canada",E21="CA"),100,IF(OR(E21="United States",E21="USA",E21="US"),IF(J21="Yes",45,75),65))) | Y21: =IF(C21="","",IF(OR(ISNUMBER(SEARCH("Program",C21)),ISNUMBER(SEARCH("Portfolio",C21)),ISNUMBER(SEARCH("Operations",C21)),ISNUMBER(SEARCH("Transformation",C21))),85,IF(ISNUMBER(SEARCH("Product Manager",C21)),55,70))) | Z21: =IF(C21="","",MIN(100,IF(I21<>"",60,10)+IF(AA21>0,MIN(40,AA21*20),0))) | AA21: =IF(T21="","",ROUND(T21*25%+U21*15%+V21*10%+W21*15%+X21*15%+Y21*10%+Z21*10%,0)) | AB21: =IF(AA21="","",IF(X21<50,"Selective / Barrier",IF(AA21>=80,"Tier 1 - Pursue",IF(AA21>=70,"Tier 2 - Pursue",IF(AA21>=60,"Tier 3 - Selective","Do Not Pursue"))))) | AC21: =IF(C21="","",IF(I21<>"","Named Contact",IF(AA21>0,"Outreach Logged","Cold"))) | AD21: =IF(B21="","",COUNTIF('Outreach Log'!$C:$C,B21)) | AE21: =IF(A21="","",IF(OR(K21="Rejected",K21="Closed"),IF(L21<>"",L21-A21,TODAY()-A21),TODAY()-A21)) | AF21: =IF(C21="","",IF(AND(AA21>=70,AC21="Cold"),"High-fit but cold",IF(AND(AA21<60,K21="Applied"),"Low-fit application",IF(AND(AA21>=70,OR(AC21="Named Contact",AC21="Outreach Logged")),"Targeted pursuit","Review"))))
B22: TELUS | C22: Senior Project Manager - Program Office, Technology & Enablement for Channels (49833) | D22: Senior | E22: Canada | F22: Toronto | G22: 68 | H22: Cold Portal | J22: No | K22: Rejected | L22: 46027 | M22: =IF(OR(L285="",A285=""),"",L285-A285) | P22: Applied date unknown (before 2026-01-05) — Elena to confirm. REJECTED 2026-01-05: "after careful consideration... decided not to move forward." No separate confirmation email found. Retroactively logged 2026-09-18 — was missing from tracker entirely. | T22: =IF(G22="","",G22) | U22: =IF(C22="","",IF(OR(ISNUMBER(SEARCH("Director",C22)),ISNUMBER(SEARCH("Lead",C22)),ISNUMBER(SEARCH("Senior",C22)),ISNUMBER(SEARCH("Sr.",C22))),90,IF(OR(ISNUMBER(SEARCH("Manager",C22)),ISNUMBER(SEARCH("Program",C22)),ISNUMBER(SEARCH("Portfolio",C22))),80,60))) | V22: =IF(C22="","",IF(OR(ISNUMBER(SEARCH("AI",C22)),ISNUMBER(SEARCH("Data",C22)),ISNUMBER(SEARCH("Technology",C22)),ISNUMBER(SEARCH("Technical",C22)),ISNUMBER(SEARCH("Engineering",C22)),ISNUMBER(SEARCH("Platform",C22)),ISNUMBER(SEARCH("Portfolio",C22))),85,65)) | W22: =IF(C22="","",MIN(100,50+IF(S22<>"",25,0)+IF(R22<>"",15,0)+IF(P22<>"",10,0))) | X22: =IF(E22="","",IF(OR(E22="Canada",E22="CA"),100,IF(OR(E22="United States",E22="USA",E22="US"),IF(J22="Yes",45,75),65))) | Y22: =IF(C22="","",IF(OR(ISNUMBER(SEARCH("Program",C22)),ISNUMBER(SEARCH("Portfolio",C22)),ISNUMBER(SEARCH("Operations",C22)),ISNUMBER(SEARCH("Transformation",C22))),85,IF(ISNUMBER(SEARCH("Product Manager",C22)),55,70))) | Z22: =IF(C22="","",MIN(100,IF(I22<>"",60,10)+IF(AA22>0,MIN(40,AA22*20),0))) | AA22: =IF(T22="","",ROUND(T22*25%+U22*15%+V22*10%+W22*15%+X22*15%+Y22*10%+Z22*10%,0)) | AB22: =IF(AA22="","",IF(X22<50,"Selective / Barrier",IF(AA22>=80,"Tier 1 - Pursue",IF(AA22>=70,"Tier 2 - Pursue",IF(AA22>=60,"Tier 3 - Selective","Do Not Pursue"))))) | AC22: =IF(C22="","",IF(I22<>"","Named Contact",IF(AA22>0,"Outreach Logged","Cold"))) | AD22: =IF(B22="","",COUNTIF('Outreach Log'!$C:$C,B22)) | AE22: =IF(A22="","",IF(OR(K22="Rejected",K22="Closed"),IF(L22<>"",L22-A22,TODAY()-A22),TODAY()-A22)) | AF22: =IF(C22="","",IF(AND(AA22>=70,AC22="Cold"),"High-fit but cold",IF(AND(AA22<60,K22="Applied"),"Low-fit application",IF(AND(AA22>=70,OR(AC22="Named Contact",AC22="Outreach Logged")),"Targeted pursuit","Review"))))
B23: TELUS | C23: Manager - Program Office (52056) | D23: Manager | E23: Canada | F23: Toronto | G23: 65 | H23: Cold Portal | J23: No | K23: Rejected | L23: 46051 | M23: =IF(OR(L286="",A286=""),"",L286-A286) | P23: Applied date unknown (before 2026-01-29) — Elena to confirm. REJECTED 2026-01-29 (role filled): "position has now been filled." No separate confirmation email found. Retroactively logged 2026-09-18 — was missing from tracker entirely. | T23: =IF(G23="","",G23) | U23: =IF(C23="","",IF(OR(ISNUMBER(SEARCH("Director",C23)),ISNUMBER(SEARCH("Lead",C23)),ISNUMBER(SEARCH("Senior",C23)),ISNUMBER(SEARCH("Sr.",C23))),90,IF(OR(ISNUMBER(SEARCH("Manager",C23)),ISNUMBER(SEARCH("Program",C23)),ISNUMBER(SEARCH("Portfolio",C23))),80,60))) | V23: =IF(C23="","",IF(OR(ISNUMBER(SEARCH("AI",C23)),ISNUMBER(SEARCH("Data",C23)),ISNUMBER(SEARCH("Technology",C23)),ISNUMBER(SEARCH("Technical",C23)),ISNUMBER(SEARCH("Engineering",C23)),ISNUMBER(SEARCH("Platform",C23)),ISNUMBER(SEARCH("Portfolio",C23))),85,65)) | W23: =IF(C23="","",MIN(100,50+IF(S23<>"",25,0)+IF(R23<>"",15,0)+IF(P23<>"",10,0))) | X23: =IF(E23="","",IF(OR(E23="Canada",E23="CA"),100,IF(OR(E23="United States",E23="USA",E23="US"),IF(J23="Yes",45,75),65))) | Y23: =IF(C23="","",IF(OR(ISNUMBER(SEARCH("Program",C23)),ISNUMBER(SEARCH("Portfolio",C23)),ISNUMBER(SEARCH("Operations",C23)),ISNUMBER(SEARCH("Transformation",C23))),85,IF(ISNUMBER(SEARCH("Product Manager",C23)),55,70))) | Z23: =IF(C23="","",MIN(100,IF(I23<>"",60,10)+IF(AA23>0,MIN(40,AA23*20),0))) | AA23: =IF(T23="","",ROUND(T23*25%+U23*15%+V23*10%+W23*15%+X23*15%+Y23*10%+Z23*10%,0)) | AB23: =IF(AA23="","",IF(X23<50,"Selective / Barrier",IF(AA23>=80,"Tier 1 - Pursue",IF(AA23>=70,"Tier 2 - Pursue",IF(AA23>=60,"Tier 3 - Selective","Do Not Pursue"))))) | AC23: =IF(C23="","",IF(I23<>"","Named Contact",IF(AA23>0,"Outreach Logged","Cold"))) | AD23: =IF(B23="","",COUNTIF('Outreach Log'!$C:$C,B23)) | AE23: =IF(A23="","",IF(OR(K23="Rejected",K23="Closed"),IF(L23<>"",L23-A23,TODAY()-A23),TODAY()-A23)) | AF23: =IF(C23="","",IF(AND(AA23>=70,AC23="Cold"),"High-fit but cold",IF(AND(AA23<60,K23="Applied"),"Low-fit application",IF(AND(AA23>=70,OR(AC23="Named Contact",AC23="Outreach Logged")),"Targeted pursuit","Review"))))
B24: TELUS | C24: Manager - Program Office, Go-To-Market Governance (51554) | D24: Manager | E24: Canada | F24: Toronto | G24: 65 | H24: Cold Portal | J24: No | K24: Rejected | L24: 46055 | M24: =IF(OR(L287="",A287=""),"",L287-A287) | P24: Applied date unknown (before 2026-02-02) — Elena to confirm. REJECTED 2026-02-02 (role filled): "position has been filled." No separate confirmation email found. Retroactively logged 2026-09-18 — was missing from tracker entirely. | T24: =IF(G24="","",G24) | U24: =IF(C24="","",IF(OR(ISNUMBER(SEARCH("Director",C24)),ISNUMBER(SEARCH("Lead",C24)),ISNUMBER(SEARCH("Senior",C24)),ISNUMBER(SEARCH("Sr.",C24))),90,IF(OR(ISNUMBER(SEARCH("Manager",C24)),ISNUMBER(SEARCH("Program",C24)),ISNUMBER(SEARCH("Portfolio",C24))),80,60))) | V24: =IF(C24="","",IF(OR(ISNUMBER(SEARCH("AI",C24)),ISNUMBER(SEARCH("Data",C24)),ISNUMBER(SEARCH("Technology",C24)),ISNUMBER(SEARCH("Technical",C24)),ISNUMBER(SEARCH("Engineering",C24)),ISNUMBER(SEARCH("Platform",C24)),ISNUMBER(SEARCH("Portfolio",C24))),85,65)) | W24: =IF(C24="","",MIN(100,50+IF(S24<>"",25,0)+IF(R24<>"",15,0)+IF(P24<>"",10,0))) | X24: =IF(E24="","",IF(OR(E24="Canada",E24="CA"),100,IF(OR(E24="United States",E24="USA",E24="US"),IF(J24="Yes",45,75),65))) | Y24: =IF(C24="","",IF(OR(ISNUMBER(SEARCH("Program",C24)),ISNUMBER(SEARCH("Portfolio",C24)),ISNUMBER(SEARCH("Operations",C24)),ISNUMBER(SEARCH("Transformation",C24))),85,IF(ISNUMBER(SEARCH("Product Manager",C24)),55,70))) | Z24: =IF(C24="","",MIN(100,IF(I24<>"",60,10)+IF(AA24>0,MIN(40,AA24*20),0))) | AA24: =IF(T24="","",ROUND(T24*25%+U24*15%+V24*10%+W24*15%+X24*15%+Y24*10%+Z24*10%,0)) | AB24: =IF(AA24="","",IF(X24<50,"Selective / Barrier",IF(AA24>=80,"Tier 1 - Pursue",IF(AA24>=70,"Tier 2 - Pursue",IF(AA24>=60,"Tier 3 - Selective","Do Not Pursue"))))) | AC24: =IF(C24="","",IF(I24<>"","Named Contact",IF(AA24>0,"Outreach Logged","Cold"))) | AD24: =IF(B24="","",COUNTIF('Outreach Log'!$C:$C,B24)) | AE24: =IF(A24="","",IF(OR(K24="Rejected",K24="Closed"),IF(L24<>"",L24-A24,TODAY()-A24),TODAY()-A24)) | AF24: =IF(C24="","",IF(AND(AA24>=70,AC24="Cold"),"High-fit but cold",IF(AND(AA24<60,K24="Applied"),"Low-fit application",IF(AND(AA24>=70,OR(AC24="Named Contact",AC24="Outreach Logged")),"Targeted pursuit","Review"))))
B25: TELUS | C25: Manager, Mobile & Home Program Management (51942) | D25: Manager | E25: Canada | F25: Toronto | G25: 60 | H25: Cold Portal | J25: No | K25: Rejected | L25: 46058 | M25: =IF(OR(L288="",A288=""),"",L288-A288) | P25: Applied date unknown (before 2026-02-05) — Elena to confirm. REJECTED 2026-02-05: "after careful consideration... decided not to move forward." No separate confirmation email found. Retroactively logged 2026-09-18 — was missing from tracker entirely. | T25: =IF(G25="","",G25) | U25: =IF(C25="","",IF(OR(ISNUMBER(SEARCH("Director",C25)),ISNUMBER(SEARCH("Lead",C25)),ISNUMBER(SEARCH("Senior",C25)),ISNUMBER(SEARCH("Sr.",C25))),90,IF(OR(ISNUMBER(SEARCH("Manager",C25)),ISNUMBER(SEARCH("Program",C25)),ISNUMBER(SEARCH("Portfolio",C25))),80,60))) | V25: =IF(C25="","",IF(OR(ISNUMBER(SEARCH("AI",C25)),ISNUMBER(SEARCH("Data",C25)),ISNUMBER(SEARCH("Technology",C25)),ISNUMBER(SEARCH("Technical",C25)),ISNUMBER(SEARCH("Engineering",C25)),ISNUMBER(SEARCH("Platform",C25)),ISNUMBER(SEARCH("Portfolio",C25))),85,65)) | W25: =IF(C25="","",MIN(100,50+IF(S25<>"",25,0)+IF(R25<>"",15,0)+IF(P25<>"",10,0))) | X25: =IF(E25="","",IF(OR(E25="Canada",E25="CA"),100,IF(OR(E25="United States",E25="USA",E25="US"),IF(J25="Yes",45,75),65))) | Y25: =IF(C25="","",IF(OR(ISNUMBER(SEARCH("Program",C25)),ISNUMBER(SEARCH("Portfolio",C25)),ISNUMBER(SEARCH("Operations",C25)),ISNUMBER(SEARCH("Transformation",C25))),85,IF(ISNUMBER(SEARCH("Product Manager",C25)),55,70))) | Z25: =IF(C25="","",MIN(100,IF(I25<>"",60,10)+IF(AA25>0,MIN(40,AA25*20),0))) | AA25: =IF(T25="","",ROUND(T25*25%+U25*15%+V25*10%+W25*15%+X25*15%+Y25*10%+Z25*10%,0)) | AB25: =IF(AA25="","",IF(X25<50,"Selective / Barrier",IF(AA25>=80,"Tier 1 - Pursue",IF(AA25>=70,"Tier 2 - Pursue",IF(AA25>=60,"Tier 3 - Selective","Do Not Pursue"))))) | AC25: =IF(C25="","",IF(I25<>"","Named Contact",IF(AA25>0,"Outreach Logged","Cold"))) | AD25: =IF(B25="","",COUNTIF('Outreach Log'!$C:$C,B25)) | AE25: =IF(A25="","",IF(OR(K25="Rejected",K25="Closed"),IF(L25<>"",L25-A25,TODAY()-A25),TODAY()-A25)) | AF25: =IF(C25="","",IF(AND(AA25>=70,AC25="Cold"),"High-fit but cold",IF(AND(AA25<60,K25="Applied"),"Low-fit application",IF(AND(AA25>=70,OR(AC25="Named Contact",AC25="Outreach Logged")),"Targeted pursuit","Review"))))
A26: HOW TO USE: Fill one row per application (row 2 is an example — replace it). Yellow = cells you fill. "Days to Response" calculates automatically. Channel: how you applied. Sponsorship Question = did the application ask if you need visa sponsorship. Mark "Ghosted (30d+)" after 30 days of silence so the dashboard counts it.
A30: 2025-09-20 | B30: Block | C30: Program Delivery Manager, Releases GTM | D30: Senior | E30: US | F30: Bay Area, CA | G30: 71 | H30: Cold Portal | J30: Yes | K30: Rejected | P30: Leads Square's biannual Releases GTM program (product launch execution) within Business Operations; executive stakeholder management, Go/No-go decisions, cross-disciplinary leadership (design/product/eng/marketing/legal/finance). 12+ years program management/consulting in Fintech/Financial Services. Good fit: strong senior program leadership and executive interaction overlap; GTM/product-launch specificity and direct Fintech/Payments experience are the main gaps. Zone-based pay $217,800-$326,800 USD. | R30: Good fit — GTM/product-launch specificity and direct Fintech/Payments experience are gaps | S30: 12+ yrs program mgmt/consulting in Fintech/Financial Services. Executive interaction. Cross-disciplinary GTM leadership (design/product/eng/marketing/legal/finance). Change management. | T30: =IF(G30="","",G30) | U30: =IF(C30="","",IF(OR(ISNUMBER(SEARCH("Director",C30)),ISNUMBER(SEARCH("Lead",C30)),ISNUMBER(SEARCH("Senior",C30)),ISNUMBER(SEARCH("Sr.",C30))),90,IF(OR(ISNUMBER(SEARCH("Manager",C30)),ISNUMBER(SEARCH("Program",C30)),ISNUMBER(SEARCH("Portfolio",C30))),80,60))) | V30: =IF(C30="","",IF(OR(ISNUMBER(SEARCH("AI",C30)),ISNUMBER(SEARCH("Data",C30)),ISNUMBER(SEARCH("Technology",C30)),ISNUMBER(SEARCH("Technical",C30)),ISNUMBER(SEARCH("Engineering",C30)),ISNUMBER(SEARCH("Platform",C30)),ISNUMBER(SEARCH("Portfolio",C30))),85,65)) | W30: =IF(C30="","",MIN(100,50+IF(S30<>"",25,0)+IF(R30<>"",15,0)+IF(P30<>"",10,0))) | X30: =IF(E30="","",IF(OR(E30="Canada",E30="CA"),100,IF(OR(E30="United States",E30="USA",E30="US"),IF(J30="Yes",45,75),65))) | Y30: =IF(C30="","",IF(OR(ISNUMBER(SEARCH("Program",C30)),ISNUMBER(SEARCH("Portfolio",C30)),ISNUMBER(SEARCH("Operations",C30)),ISNUMBER(SEARCH("Transformation",C30))),85,IF(ISNUMBER(SEARCH("Product Manager",C30)),55,70))) | Z30: =IF(C30="","",MIN(100,IF(I30<>"",60,10)+IF(AA30>0,MIN(40,AA30*20),0))) | AA30: =IF(T30="","",ROUND(T30*25%+U30*15%+V30*10%+W30*15%+X30*15%+Y30*10%+Z30*10%,0)) | AB30: =IF(AA30="","",IF(X30<50,"Selective / Barrier",IF(AA30>=80,"Tier 1 - Pursue",IF(AA30>=70,"Tier 2 - Pursue",IF(AA30>=60,"Tier 3 - Selective","Do Not Pursue"))))) | AC30: =IF(C30="","",IF(I30<>"","Named Contact",IF(AA30>0,"Outreach Logged","Cold"))) | AD30: =IF(B30="","",COUNTIF('Outreach Log'!$C:$C,B30)) | AE30: =IF(A30="","",IF(OR(K30="Rejected",K30="Closed"),IF(L30<>"",L30-A30,TODAY()-A30),TODAY()-A30)) | AF30: =IF(C30="","",IF(AND(AA30>=70,AC30="Cold"),"High-fit but cold",IF(AND(AA30<60,K30="Applied"),"Low-fit application",IF(AND(AA30>=70,OR(AC30="Named Contact",AC30="Outreach Logged")),"Targeted pursuit","Review"))))
